Workbook

Sheet Legenda
A1: Coleta de baseline (Período A): 12 fluxos × 20 rajadas
A3: Como preencher (aba Coleta)
A4: 1. Rode um ping de aquecimento no Probe (para o ARP não distorcer) e só depois a rajada: ping -n 3 <IP do Alvo>.
A5: 2. Para cada rajada, preencha a linha do fluxo: timestamp (UTC) e os 3 tempos em rtt1, rtt2 e rtt3 (células amarelas, texto azul).
A6: 3. Tempo exibido como <1ms: digite 0.5. Tempo em ms: digite o número (ex.: 12).
A7: 4. Pacote sem resposta (Request timed out ou Destination host unreachable): digite T (nunca 0).
A8: 5. Todo o resto é calculado por fórmula: sent, rcvd, latência, perda, jitter, timeout e a aba Baseline.
A10: Exemplo (não faz parte dos dados)
A11: Rajada: Request timed out, 12 ms, 1 ms → rtt1 = T, rtt2 = 12, rtt3 = 1 → sent 3, rcvd 2, latência 6,5 ms, perda 33,3%, jitter 11 ms, timeout 0.
A12: Timestamp de exemplo: 2026-10-17T18:30:00Z
A14: Critérios adotados
A15: • latencia_ms = média dos RTT válidos da rajada; vazio se rcvd = 0 (nunca 0).
... A22: Exportar o CSV: quando terminar, abra a aba medicoes_pt e use Arquivo → Salvar como → CSV (só a aba ativa é salva) em data/medicoes_pt.csv.

Sheet Coleta
A1: rajada | B1: fluxo_id | C1: probe_id | D1: periodo | E1: cenario | F1: timestamp (UTC) | G1: rtt1 | H1: rtt2 | I1: rtt3 | J1: sent | K1: rcvd | L1: latencia_ms | M1: perda_pct | N1: |Δ| 1-2 | O1: |Δ| 2-3 | P1: jitter_ms | Q1: timeout_atual | R1: |lat − mediana|
A2: 1 | B2: Probe-BR|192.168.10.10 | C2: Probe-BR | D2: A | E2: Normal | F2: 2026-10-18T01:50:00Z | G2: 0.5 | H2: 0.5 | I2: 0.5 | J2: =IF(COUNTA(G2:I2)=0,"",3) -> 3 | K2: =IF(J2="","",COUNT(G2:I2)) -> 3 | L2: =IF(OR(K2="",K2=0),"",AVERAGE(G2:I2)) -> 0.5 | M2: =IF(K2="","",(J2-K2)/J2*100) -> 0 | N2: =IF(AND(ISNUMBER(G2),ISNUMBER(H2)),ABS(H2-G2),"") -> 0 | O2: =IF(AND(ISNUMBER(H2),ISNUMBER(I2)),ABS(I2-H2),"") -> 0 | P2: =IF(K2="","",IFERROR(AVERAGE(N2,O2),"")) -> 0 | Q2: =IF(K2="","",IF(K2=0,1,0)) -> 0 | R2: =IF(OR(L2="",Baseline!$C$5=""),"",ABS(L2-Baseline!$C$5)) -> 0
A3: 2 | B3: Probe-BR|192.168.10.10 | C3: Probe-BR | D3: A | E3: Normal | F3: 2026-10-18T02:08:00Z | G3: 0.5 | H3: 0.5 | I3: 0.5 | J3: =IF(COUNTA(G3:I3)=0,"",3) -> 3 | K3: =IF(J3="","",COUNT(G3:I3)) -> 3 | L3: =IF(OR(K3="",K3=0),"",AVERAGE(G3:I3)) -> 0.5 | M3: =IF(K3="","",(J3-K3)/J3*100) -> 0 | N3: =IF(AND(ISNUMBER(G3),ISNUMBER(H3)),ABS(H3-G3),"") -> 0 | O3: =IF(AND(ISNUMBER(H3),ISNUMBER(I3)),ABS(I3-H3),"") -> 0 | P3: =IF(K3="","",IFERROR(AVERAGE(N3,O3),"")) -> 0 | Q3: =IF(K3="","",IF(K3=0,1,0)) -> 0 | R3: =IF(OR(L3="",Baseline!$C$5=""),"",ABS(L3-Baseline!$C$5)) -> 0
A4: 3 | B4: Probe-BR|192.168.10.10 | C4: Probe-BR | D4: A | E4: Normal | F4: 2026-10-18T02:15:00Z | G4: 0.5 | H4: 0.5 | I4: 0.5 | J4: =IF(COUNTA(G4:I4)=0,"",3) -> 3 | K4: =IF(J4="","",COUNT(G4:I4)) -> 3 | L4: =IF(OR(K4="",K4=0),"",AVERAGE(G4:I4)) -> 0.5 | M4: =IF(K4="","",(J4-K4)/J4*100) -> 0 | N4: =IF(AND(ISNUMBER(G4),ISNUMBER(H4)),ABS(H4-G4),"") -> 0 | O4: =IF(AND(ISNUMBER(H4),ISNUMBER(I4)),ABS(I4-H4),"") -> 0 | P4: =IF(K4="","",IFERROR(AVERAGE(N4,O4),"")) -> 0 | Q4: =IF(K4="","",IF(K4=0,1,0)) -> 0 | R4: =IF(OR(L4="",Baseline!$C$5=""),"",ABS(L4-Baseline!$C$5)) -> 0
A5: 4 | B5: Probe-BR|192.168.10.10 | C5: Probe-BR | D5: A | E5: Normal | F5: 2026-10-18T02:20:00Z | G5: 0.5 | H5: 0.5 | I5: 14 | J5: =IF(COUNTA(G5:I5)=0,"",3) -> 3 | K5: =IF(J5="","",COUNT(G5:I5)) -> 3 | L5: =IF(OR(K5="",K5=0),"",AVERAGE(G5:I5)) -> 5 | M5: =IF(K5="","",(J5-K5)/J5*100) -> 0 | N5: =IF(AND(ISNUMBER(G5),ISNUMBER(H5)),ABS(H5-G5),"") -> 0 | O5: =IF(AND(ISNUMBER(H5),ISNUMBER(I5)),ABS(I5-H5),"") -> 13.5 | P5: =IF(K5="","",IFERROR(AVERAGE(N5,O5),"")) -> 6.75 | Q5: =IF(K5="","",IF(K5=0,1,0)) -> 0 | R5: =IF(OR(L5="",Baseline!$C$5=""),"",ABS(L5-Baseline!$C$5)) -> 4.5
A6: 5 | B6: Probe-BR|192.168.10.10 | C6: Probe-BR | D6: A | E6: Normal | F6: 2026-10-18T02:36:00Z | G6: 0.5 | H6: 1 | I6: 0.5 | J6: =IF(COUNTA(G6:I6)=0,"",3) -> 3 | K6: =IF(J6="","",COUNT(G6:I6)) -> 3 | L6: =IF(OR(K6="",K6=0),"",AVERAGE(G6:I6)) -> 0.66666667 | M6: =IF(K6="","",(J6-K6)/J6*100) -> 0 | N6: =IF(AND(ISNUMBER(G6),ISNUMBER(H6)),ABS(H6-G6),"") -> 0.5 | O6: =IF(AND(ISNUMBER(H6),ISNUMBER(I6)),ABS(I6-H6),"") -> 0.5 | P6: =IF(K6="","",IFERROR(AVERAGE(N6,O6),"")) -> 0.5 | Q6: =IF(K6="","",IF(K6=0,1,0)) -> 0 | R6: =IF(OR(L6="",Baseline!$C$5=""),"",ABS(L6-Baseline!$C$5)) -> 0.16666667
A7: 6 | B7: Probe-BR|192.168.10.10 | C7: Probe-BR | D7: A | E7: Normal | F7: 2026-10-18T02:39:00Z | G7: 0.5 | H7: 1 | I7: 0.5 | J7: =IF(COUNTA(G7:I7)=0,"",3) -> 3 | K7: =IF(J7="","",COUNT(G7:I7)) -> 3 | L7: =IF(OR(K7="",K7=0),"",AVERAGE(G7:I7)) -> 0.66666667 | M7: =IF(K7="","",(J7-K7)/J7*100) -> 0 | N7: =IF(AND(ISNUMBER(G7),ISNUMBER(H7)),ABS(H7-G7),"") -> 0.5 | O7: =IF(AND(ISNUMBER(H7),ISNUMBER(I7)),ABS(I7-H7),"") -> 0.5 | P7: =IF(K7="","",IFERROR(AVERAGE(N7,O7),"")) -> 0.5 | Q7: =IF(K7="","",IF(K7=0,1,0)) -> 0 | R7: =IF(OR(L7="",Baseline!$C$5=""),"",ABS(L7-Baseline!$C$5)) -> 0.16666667
A8: 7 | B8: Probe-BR|192.168.10.10 | C8: Probe-BR | D8: A | E8: Normal | F8: 2026-10-18T02:40:00Z | G8: 0.5 | H8: 0.5 | I8: 0.5 | J8: =IF(COUNTA(G8:I8)=0,"",3) -> 3 | K8: =IF(J8="","",COUNT(G8:I8)) -> 3 | L8: =IF(OR(K8="",K8=0),"",AVERAGE(G8:I8)) -> 0.5 | M8: =IF(K8="","",(J8-K8)/J8*100) -> 0 | N8: =IF(AND(ISNUMBER(G8),ISNUMBER(H8)),ABS(H8-G8),"") -> 0 | O8: =IF(AND(ISNUMBER(H8),ISNUMBER(I8)),ABS(I8-H8),"") -> 0 | P8: =IF(K8="","",IFERROR(AVERAGE(N8,O8),"")) -> 0 | Q8: =IF(K8="","",IF(K8=0,1,0)) -> 0 | R8: =IF(OR(L8="",Baseline!$C$5=""),"",ABS(L8-Baseline!$C$5)) -> 0
A9: 8 | B9: Probe-BR|192.168.10.10 | C9: Probe-BR | D9: A | E9: Normal | F9: 2026-10-18T02:43:00Z | G9: 0.5 | H9: 1 | I9: 0.5 | J9: =IF(COUNTA(G9:I9)=0,"",3) -> 3 | K9: =IF(J9="","",COUNT(G9:I9)) -> 3 | L9: =IF(OR(K9="",K9=0),"",AVERAGE(G9:I9)) -> 0.66666667 | M9: =IF(K9="","",(J9-K9)/J9*100) -> 0 | N9: =IF(AND(ISNUMBER(G9),ISNUMBER(H9)),ABS(H9-G9),"") -> 0.5 | O9: =IF(AND(ISNUMBER(H9),ISNUMBER(I9)),ABS(I9-H9),"") -> 0.5 | P9: =IF(K9="","",IFERROR(AVERAGE(N9,O9),"")) -> 0.5 | Q9: =IF(K9="","",IF(K9=0,1,0)) -> 0 | R9: =IF(OR(L9="",Baseline!$C$5=""),"",ABS(L9-Baseline!$C$5)) -> 0.16666667
A10: 9 | B10: Probe-BR|192.168.10.10 | C10: Probe-BR | D10: A | E10: Normal | F10: 2026-10-18T02:46:00Z | G10: 0.5 | H10: 0.5 | I10: 0.5 | J10: =IF(COUNTA(G10:I10)=0,"",3) -> 3 | K10: =IF(J10="","",COUNT(G10:I10)) -> 3 | L10: =IF(OR(K10="",K10=0),"",AVERAGE(G10:I10)) -> 0.5 | M10: =IF(K10="","",(J10-K10)/J10*100) -> 0 | N10: =IF(AND(ISNUMBER(G10),ISNUMBER(H10)),ABS(H10-G10),"") -> 0 | O10: =IF(AND(ISNUMBER(H10),ISNUMBER(I10)),ABS(I10-H10),"") -> 0 | P10: =IF(K10="","",IFERROR(AVERAGE(N10,O10),"")) -> 0 | Q10: =IF(K10="","",IF(K10=0,1,0)) -> 0 | R10: =IF(OR(L10="",Baseline!$C$5=""),"",ABS(L10-Baseline!$C$5)) -> 0
A11: 10 | B11: Probe-BR|192.168.10.10 | C11: Probe-BR | D11: A | E11: Normal | F11: 2026-10-18T02:49:00Z | G11: 0.5 | H11: 0.5 | I11: 0.5 | J11: =IF(COUNTA(G11:I11)=0,"",3) -> 3 | K11: =IF(J11="","",COUNT(G11:I11)) -> 3 | L11: =IF(OR(K11="",K11=0),"",AVERAGE(G11:I11)) -> 0.5 | M11: =IF(K11="","",(J11-K11)/J11*100) -> 0 | N11: =IF(AND(ISNUMBER(G11),ISNUMBER(H11)),ABS(H11-G11),"") -> 0 | O11: =IF(AND(ISNUMBER(H11),ISNUMBER(I11)),ABS(I11-H11),"") -> 0 | P11: =IF(K11="","",IFERROR(AVERAGE(N11,O11),"")) -> 0 | Q11: =IF(K11="","",IF(K11=0,1,0)) -> 0 | R11: =IF(OR(L11="",Baseline!$C$5=""),"",ABS(L11-Baseline!$C$5)) -> 0
A12: 11 | B12: Probe-BR|192.168.10.10 | C12: Probe-BR | D12: A | E12: Normal | F12: 2026-10-18T02:51:00Z | G12: 0.5 | H12: 0.5 | I12: 0.5 | J12: =IF(COUNTA(G12:I12)=0,"",3) -> 3 | K12: =IF(J12="","",COUNT(G12:I12)) -> 3 | L12: =IF(OR(K12="",K12=0),"",AVERAGE(G12:I12)) -> 0.5 | M12: =IF(K12="","",(J12-K12)/J12*100) -> 0 | N12: =IF(AND(ISNUMBER(G12),ISNUMBER(H12)),ABS(H12-G12),"") -> 0 | O12: =IF(AND(ISNUMBER(H12),ISNUMBER(I12)),ABS(I12-H12),"") -> 0 | P12: =IF(K12="","",IFERROR(AVERAGE(N12,O12),"")) -> 0 | Q12: =IF(K12="","",IF(K12=0,1,0)) -> 0 | R12: =IF(OR(L12="",Baseline!$C$5=""),"",ABS(L12-Baseline!$C$5)) -> 0
A13: 12 | B13: Probe-BR|192.168.10.10 | C13: Probe-BR | D13: A | E13: Normal | F13: 2026-10-18T02:53:00Z | G13: 22 | H13: 0.5 | I13: 0.5 | J13: =IF(COUNTA(G13:I13)=0,"",3) -> 3 | K13: =IF(J13="","",COUNT(G13:I13)) -> 3 | L13: =IF(OR(K13="",K13=0),"",AVERAGE(G13:I13)) -> 7.6666667 | M13: =IF(K13="","",(J13-K13)/J13*100) -> 0 | N13: =IF(AND(ISNUMBER(G13),ISNUMBER(H13)),ABS(H13-G13),"") -> 21.5 | O13: =IF(AND(ISNUMBER(H13),ISNUMBER(I13)),ABS(I13-H13),"") -> 0 | P13: =IF(K13="","",IFERROR(AVERAGE(N13,O13),"")) -> 10.75 | Q13: =IF(K13="","",IF(K13=0,1,0)) -> 0 | R13: =IF(OR(L13="",Baseline!$C$5=""),"",ABS(L13-Baseline!$C$5)) -> 7.1666667
... A21: 20 | B21: Probe-BR|192.168.10.10 | C21: Probe-BR | D21: A | E21: Normal | F21: 2026-10-18T03:09:00Z | G21: 0.5 | H21: 0.5 | I21: 0.5 | J21: =IF(COUNTA(G21:I21)=0,"",3) -> 3 | K21: =IF(J21="","",COUNT(G21:I21)) -> 3 | L21: =IF(OR(K21="",K21=0),"",AVERAGE(G21:I21)) -> 0.5 | M21: =IF(K21="","",(J21-K21)/J21*100) -> 0 | N21: =IF(AND(ISNUMBER(G21),ISNUMBER(H21)),ABS(H21-G21),"") -> 0 | O21: =IF(AND(ISNUMBER(H21),ISNUMBER(I21)),ABS(I21-H21),"") -> 0 | P21: =IF(K21="","",IFERROR(AVERAGE(N21,O21),"")) -> 0 | Q21: =IF(K21="","",IF(K21=0,1,0)) -> 0 | R21: =IF(OR(L21="",Baseline!$C$5=""),"",ABS(L21-Baseline!$C$5)) -> 0
A22: 1 | B22: Probe-BR|192.168.11.10 | C22: Probe-BR | D22: A | E22: Normal | F22: 2026-10-18T03:11:00Z | G22: T | H22: 21 | I22: 0.5 | J22: =IF(COUNTA(G22:I22)=0,"",3) -> 3 | K22: =IF(J22="","",COUNT(G22:I22)) -> 2 | L22: =IF(OR(K22="",K22=0),"",AVERAGE(G22:I22)) -> 10.75 | M22: =IF(K22="","",(J22-K22)/J22*100) -> 33.333333 | N22: =IF(AND(ISNUMBER(G22),ISNUMBER(H22)),ABS(H22-G22),"") | O22: =IF(AND(ISNUMBER(H22),ISNUMBER(I22)),ABS(I22-H22),"") -> 20.5 | P22: =IF(K22="","",IFERROR(AVERAGE(N22,O22),"")) -> 20.5 | Q22: =IF(K22="","",IF(K22=0,1,0)) -> 0 | R22: =IF(OR(L22="",Baseline!$C$6=""),"",ABS(L22-Baseline!$C$6)) -> 10.25
A23: 2 | B23: Probe-BR|192.168.11.10 | C23: Probe-BR | D23: A | E23: Normal | F23: 2026-10-18T03:14:00Z | G23: 0.5 | H23: 0.5 | I23: 0.5 | J23: =IF(COUNTA(G23:I23)=0,"",3) -> 3 | K23: =IF(J23="","",COUNT(G23:I23)) -> 3 | L23: =IF(OR(K23="",K23=0),"",AVERAGE(G23:I23)) -> 0.5 | M23: =IF(K23="","",(J23-K23)/J23*100) -> 0 | N23: =IF(AND(ISNUMBER(G23),ISNUMBER(H23)),ABS(H23-G23),"") -> 0 | O23: =IF(AND(ISNUMBER(H23),ISNUMBER(I23)),ABS(I23-H23),"") -> 0 | P23: =IF(K23="","",IFERROR(AVERAGE(N23,O23),"")) -> 0 | Q23: =IF(K23="","",IF(K23=0,1,0)) -> 0 | R23: =IF(OR(L23="",Baseline!$C$6=""),"",ABS(L23-Baseline!$C$6)) -> 0
A24: 3 | B24: Probe-BR|192.168.11.10 | C24: Probe-BR | D24: A | E24: Normal | F24: 2026-10-18T03:23:00Z | G24: 0.5 | H24: 0.5 | I24: 0.5 | J24: =IF(COUNTA(G24:I24)=0,"",3) -> 3 | K24: =IF(J24="","",COUNT(G24:I24)) -> 3 | L24: =IF(OR(K24="",K24=0),"",AVERAGE(G24:I24)) -> 0.5 | M24: =IF(K24="","",(J24-K24)/J24*100) -> 0 | N24: =IF(AND(ISNUMBER(G24),ISNUMBER(H24)),ABS(H24-G24),"") -> 0 | O24: =IF(AND(ISNUMBER(H24),ISNUMBER(I24)),ABS(I24-H24),"") -> 0 | P24: =IF(K24="","",IFERROR(AVERAGE(N24,O24),"")) -> 0 | Q24: =IF(K24="","",IF(K24=0,1,0)) -> 0 | R24: =IF(OR(L24="",Baseline!$C$6=""),"",ABS(L24-Baseline!$C$6)) -> 0
A25: 4 | B25: Probe-BR|192.168.11.10 | C25: Probe-BR | D25: A | E25: Normal | F25: 2026-10-18T03:25:00Z | G25: 0.5 | H25: 0.5 | I25: 0.5 | J25: =IF(COUNTA(G25:I25)=0,"",3) -> 3 | K25: =IF(J25="","",COUNT(G25:I25)) -> 3 | L25: =IF(OR(K25="",K25=0),"",AVERAGE(G25:I25)) -> 0.5 | M25: =IF(K25="","",(J25-K25)/J25*100) -> 0 | N25: =IF(AND(ISNUMBER(G25),ISNUMBER(H25)),ABS(H25-G25),"") -> 0 | O25: =IF(AND(ISNUMBER(H25),ISNUMBER(I25)),ABS(I25-H25),"") -> 0 | P25: =IF(K25="","",IFERROR(AVERAGE(N25,O25),"")) -> 0 | Q25: =IF(K25="","",IF(K25=0,1,0)) -> 0 | R25: =IF(OR(L25="",Baseline!$C$6=""),"",ABS(L25-Baseline!$C$6)) -> 0
A26: 5 | B26: Probe-BR|192.168.11.10 | C26: Probe-BR | D26: A | E26: Normal | F26: 2026-10-18T03:27:00Z | G26: 0.5 | H26: 15 | I26: 0.5 | J26: =IF(COUNTA(G26:I26)=0,"",3) -> 3 | K26: =IF(J26="","",COUNT(G26:I26)) -> 3 | L26: =IF(OR(K26="",K26=0),"",AVERAGE(G26:I26)) -> 5.3333333 | M26: =IF(K26="","",(J26-K26)/J26*100) -> 0 | N26: =IF(AND(ISNUMBER(G26),ISNUMBER(H26)),ABS(H26-G26),"") -> 14.5 | O26: =IF(AND(ISNUMBER(H26),ISNUMBER(I26)),ABS(I26-H26),"") -> 14.5 | P26: =IF(K26="","",IFERROR(AVERAGE(N26,O26),"")) -> 14.5 | Q26: =IF(K26="","",IF(K26=0,1,0)) -> 0 | R26: =IF(OR(L26="",Baseline!$C$6=""),"",ABS(L26-Baseline!$C$6)) -> 4.8333333
A27: 6 | B27: Probe-BR|192.168.11.10 | C27: Probe-BR | D27: A | E27: Normal | F27: 2026-10-18T03:30:00Z | G27: 0.5 | H27: 0.5 | I27: 0.5 | J27: =IF(COUNTA(G27:I27)=0,"",3) -> 3 | K27: =IF(J27="","",COUNT(G27:I27)) -> 3 | L27: =IF(OR(K27="",K27=0),"",AVERAGE(G27:I27)) -> 0.5 | M27: =IF(K27="","",(J27-K27)/J27*100) -> 0 | N27: =IF(AND(ISNUMBER(G27),ISNUMBER(H27)),ABS(H27-G27),"") -> 0 | O27: =IF(AND(ISNUMBER(H27),ISNUMBER(I27)),ABS(I27-H27),"") -> 0 | P27: =IF(K27="","",IFERROR(AVERAGE(N27,O27),"")) -> 0 | Q27: =IF(K27="","",IF(K27=0,1,0)) -> 0 | R27: =IF(OR(L27="",Baseline!$C$6=""),"",ABS(L27-Baseline!$C$6)) -> 0
A28: 7 | B28: Probe-BR|192.168.11.10 | C28: Probe-BR | D28: A | E28: Normal | F28: 2026-10-18T03:31:00Z | G28: 0.5 | H28: 20 | I28: 0.5 | J28: =IF(COUNTA(G28:I28)=0,"",3) -> 3 | K28: =IF(J28="","",COUNT(G28:I28)) -> 3 | L28: =IF(OR(K28="",K28=0),"",AVERAGE(G28:I28)) -> 7 | M28: =IF(K28="","",(J28-K28)/J28*100) -> 0 | N28: =IF(AND(ISNUMBER(G28),ISNUMBER(H28)),ABS(H28-G28),"") -> 19.5 | O28: =IF(AND(ISNUMBER(H28),ISNUMBER(I28)),ABS(I28-H28),"") -> 19.5 | P28: =IF(K28="","",IFERROR(AVERAGE(N28,O28),"")) -> 19.5 | Q28: =IF(K28="","",IF(K28=0,1,0)) -> 0 | R28: =IF(OR(L28="",Baseline!$C$6=""),"",ABS(L28-Baseline!$C$6)) -> 6.5
A29: 8 | B29: Probe-BR|192.168.11.10 | C29: Probe-BR | D29: A | E29: Normal | F29: 2026-10-18T03:32:00Z | G29: 21 | H29: 0.5 | I29: 0.5 | J29: =IF(COUNTA(G29:I29)=0,"",3) -> 3 | K29: =IF(J29="","",COUNT(G29:I29)) -> 3 | L29: =IF(OR(K29="",K29=0),"",AVERAGE(G29:I29)) -> 7.3333333 | M29: =IF(K29="","",(J29-K29)/J29*100) -> 0 | N29: =IF(AND(ISNUMBER(G29),ISNUMBER(H29)),ABS(H29-G29),"") -> 20.5 | O29: =IF(AND(ISNUMBER(H29),ISNUMBER(I29)),ABS(I29-H29),"") -> 0 | P29: =IF(K29="","",IFERROR(AVERAGE(N29,O29),"")) -> 10.25 | Q29: =IF(K29="","",IF(K29=0,1,0)) -> 0 | R29: =IF(OR(L29="",Baseline!$C$6=""),"",ABS(L29-Baseline!$C$6)) -> 6.8333333
A30: 9 | B30: Probe-BR|192.168.11.10 | C30: Probe-BR | D30: A | E30: Normal | F30: 2026-10-18T03:34:00Z | G30: 0.5 | H30: 0.5 | I30: 16 | J30: =IF(COUNTA(G30:I30)=0,"",3) -> 3 | K30: =IF(J30="","",COUNT(G30:I30)) -> 3 | L30: =IF(OR(K30="",K30=0),"",AVERAGE(G30:I30)) -> 5.6666667 | M30: =IF(K30="","",(J30-K30)/J30*100) -> 0 | N30: =IF(AND(ISNUMBER(G30),ISNUMBER(H30)),ABS(H30-G30),"") -> 0 | O30: =IF(AND(ISNUMBER(H30),ISNUMBER(I30)),ABS(I30-H30),"") -> 15.5 | P30: =IF(K30="","",IFERROR(AVERAGE(N30,O30),"")) -> 7.75 | Q30: =IF(K30="","",IF(K30=0,1,0)) -> 0 | R30: =IF(OR(L30="",Baseline!$C$6=""),"",ABS(L30-Baseline!$C$6)) -> 5.1666667
A31: 10 | B31: Probe-BR|192.168.11.10 | C31: Probe-BR | D31: A | E31: Normal | F31: 2026-10-18T03:36:00Z | G31: 0.5 | H31: 0.5 | I31: 3 | J31: =IF(COUNTA(G31:I31)=0,"",3) -> 3 | K31: =IF(J31="","",COUNT(G31:I31)) -> 3 | L31: =IF(OR(K31="",K31=0),"",AVERAGE(G31:I31)) -> 1.3333333 | M31: =IF(K31="","",(J31-K31)/J31*100) -> 0 | N31: =IF(AND(ISNUMBER(G31),ISNUMBER(H31)),ABS(H31-G31),"") -> 0 | O31: =IF(AND(ISNUMBER(H31),ISNUMBER(I31)),ABS(I31-H31),"") -> 2.5 | P31: =IF(K31="","",IFERROR(AVERAGE(N31,O31),"")) -> 1.25 | Q31: =IF(K31="","",IF(K31=0,1,0)) -> 0 | R31: =IF(OR(L31="",Baseline!$C$6=""),"",ABS(L31-Baseline!$C$6)) -> 0.83333333
A32: 11 | B32: Probe-BR|192.168.11.10 | C32: Probe-BR | D32: A | E32: Normal | F32: 2026-10-18T03:38:00Z | G32: 0.5 | H32: 0.5 | I32: 0.5 | J32: =IF(COUNTA(G32:I32)=0,"",3) -> 3 | K32: =IF(J32="","",COUNT(G32:I32)) -> 3 | L32: =IF(OR(K32="",K32=0),"",AVERAGE(G32:I32)) -> 0.5 | M32: =IF(K32="","",(J32-K32)/J32*100) -> 0 | N32: =IF(AND(ISNUMBER(G32),ISNUMBER(H32)),ABS(H32-G32),"") -> 0 | O32: =IF(AND(ISNUMBER(H32),ISNUMBER(I32)),ABS(I32-H32),"") -> 0 | P32: =IF(K32="","",IFERROR(AVERAGE(N32,O32),"")) -> 0 | Q32: =IF(K32="","",IF(K32=0,1,0)) -> 0 | R32: =IF(OR(L32="",Baseline!$C$6=""),"",ABS(L32-Baseline!$C$6)) -> 0
A33: 12 | B33: Probe-BR|192.168.11.10 | C33: Probe-BR | D33: A | E33: Normal | F33: 2026-10-18T03:39:00Z | G33: 0.5 | H33: 0.5 | I33: 0.5 | J33: =IF(COUNTA(G33:I33)=0,"",3) -> 3 | K33: =IF(J33="","",COUNT(G33:I33)) -> 3 | L33: =IF(OR(K33="",K33=0),"",AVERAGE(G33:I33)) -> 0.5 | M33: =IF(K33="","",(J33-K33)/J33*100) -> 0 | N33: =IF(AND(ISNUMBER(G33),ISNUMBER(H33)),ABS(H33-G33),"") -> 0 | O33: =IF(AND(ISNUMBER(H33),ISNUMBER(I33)),ABS(I33-H33),"") -> 0 | P33: =IF(K33="","",IFERROR(AVERAGE(N33,O33),"")) -> 0 | Q33: =IF(K33="","",IF(K33=0,1,0)) -> 0 | R33: =IF(OR(L33="",Baseline!$C$6=""),"",ABS(L33-Baseline!$C$6)) -> 0
A34: 13 | B34: Probe-BR|192.168.11.10 | C34: Probe-BR | D34: A | E34: Normal | F34: 2026-10-18T03:41:00Z | G34: 0.5 | H34: 0.5 | I34: 0.5 | J34: =IF(COUNTA(G34:I34)=0,"",3) -> 3 | K34: =IF(J34="","",COUNT(G34:I34)) -> 3 | L34: =IF(OR(K34="",K34=0),"",AVERAGE(G34:I34)) -> 0.5 | M34: =IF(K34="","",(J34-K34)/J34*100) -> 0 | N34: =IF(AND(ISNUMBER(G34),ISNUMBER(H34)),ABS(H34-G34),"") -> 0 | O34: =IF(AND(ISNUMBER(H34),ISNUMBER(I34)),ABS(I34-H34),"") -> 0 | P34: =IF(K34="","",IFERROR(AVERAGE(N34,O34),"")) -> 0 | Q34: =IF(K34="","",IF(K34=0,1,0)) -> 0 | R34: =IF(OR(L34="",Baseline!$C$6=""),"",ABS(L34-Baseline!$C$6)) -> 0
... A41: 20 | B41: Probe-BR|192.168.11.10 | C41: Probe-BR | D41: A | E41: Normal | F41: 2026-10-18T03:48:00Z | G41: 0.5 | H41: 0.5 | I41: 0.5 | J41: =IF(COUNTA(G41:I41)=0,"",3) -> 3 | K41: =IF(J41="","",COUNT(G41:I41)) -> 3 | L41: =IF(OR(K41="",K41=0),"",AVERAGE(G41:I41)) -> 0.5 | M41: =IF(K41="","",(J41-K41)/J41*100) -> 0 | N41: =IF(AND(ISNUMBER(G41),ISNUMBER(H41)),ABS(H41-G41),"") -> 0 | O41: =IF(AND(ISNUMBER(H41),ISNUMBER(I41)),ABS(I41-H41),"") -> 0 | P41: =IF(K41="","",IFERROR(AVERAGE(N41,O41),"")) -> 0 | Q41: =IF(K41="","",IF(K41=0,1,0)) -> 0 | R41: =IF(OR(L41="",Baseline!$C$6=""),"",ABS(L41-Baseline!$C$6)) -> 0
A42: 1 | B42: Probe-BR|192.168.12.10 | C42: Probe-BR | D42: A | E42: Normal | F42: 2026-10-18T03:52:00Z | G42: T | H42: 0.5 | I42: 0.5 | J42: =IF(COUNTA(G42:I42)=0,"",3) -> 3 | K42: =IF(J42="","",COUNT(G42:I42)) -> 2 | L42: =IF(OR(K42="",K42=0),"",AVERAGE(G42:I42)) -> 0.5 | M42: =IF(K42="","",(J42-K42)/J42*100) -> 33.333333 | N42: =IF(AND(ISNUMBER(G42),ISNUMBER(H42)),ABS(H42-G42),"") | O42: =IF(AND(ISNUMBER(H42),ISNUMBER(I42)),ABS(I42-H42),"") -> 0 | P42: =IF(K42="","",IFERROR(AVERAGE(N42,O42),"")) -> 0 | Q42: =IF(K42="","",IF(K42=0,1,0)) -> 0 | R42: =IF(OR(L42="",Baseline!$C$7=""),"",ABS(L42-Baseline!$C$7)) -> 0
A43: 2 | B43: Probe-BR|192.168.12.10 | C43: Probe-BR | D43: A | E43: Normal | F43: 2026-10-18T03:54:00Z | G43: 0.5 | H43: 0.5 | I43: 0.5 | J43: =IF(COUNTA(G43:I43)=0,"",3) -> 3 | K43: =IF(J43="","",COUNT(G43:I43)) -> 3 | L43: =IF(OR(K43="",K43=0),"",AVERAGE(G43:I43)) -> 0.5 | M43: =IF(K43="","",(J43-K43)/J43*100) -> 0 | N43: =IF(AND(ISNUMBER(G43),ISNUMBER(H43)),ABS(H43-G43),"") -> 0 | O43: =IF(AND(ISNUMBER(H43),ISNUMBER(I43)),ABS(I43-H43),"") -> 0 | P43: =IF(K43="","",IFERROR(AVERAGE(N43,O43),"")) -> 0 | Q43: =IF(K43="","",IF(K43=0,1,0)) -> 0 | R43: =IF(OR(L43="",Baseline!$C$7=""),"",ABS(L43-Baseline!$C$7)) -> 0
A44: 3 | B44: Probe-BR|192.168.12.10 | C44: Probe-BR | D44: A | E44: Normal | F44: 2026-10-18T03:55:00Z | G44: 0.5 | H44: 0.5 | I44: 1 | J44: =IF(COUNTA(G44:I44)=0,"",3) -> 3 | K44: =IF(J44="","",COUNT(G44:I44)) -> 3 | L44: =IF(OR(K44="",K44=0),"",AVERAGE(G44:I44)) -> 0.66666667 | M44: =IF(K44="","",(J44-K44)/J44*100) -> 0 | N44: =IF(AND(ISNUMBER(G44),ISNUMBER(H44)),ABS(H44-G44),"") -> 0 | O44: =IF(AND(ISNUMBER(H44),ISNUMBER(I44)),ABS(I44-H44),"") -> 0.5 | P44: =IF(K44="","",IFERROR(AVERAGE(N44,O44),"")) -> 0.25 | Q44: =IF(K44="","",IF(K44=0,1,0)) -> 0 | R44: =IF(OR(L44="",Baseline!$C$7=""),"",ABS(L44-Baseline!$C$7)) -> 0.16666667
A45: 4 | B45: Probe-BR|192.168.12.10 | C45: Probe-BR | D45: A | E45: Normal | F45: 2026-10-18T03:57:00Z | G45: 0.5 | H45: 0.5 | I45: 1 | J45: =IF(COUNTA(G45:I45)=0,"",3) -> 3 | K45: =IF(J45="","",COUNT(G45:I45)) -> 3 | L45: =IF(OR(K45="",K45=0),"",AVERAGE(G45:I45)) -> 0.66666667 | M45: =IF(K45="","",(J45-K45)/J45*100) -> 0 | N45: =IF(AND(ISNUMBER(G45),ISNUMBER(H45)),ABS(H45-G45),"") -> 0 | O45: =IF(AND(ISNUMBER(H45),ISNUMBER(I45)),ABS(I45-H45),"") -> 0.5 | P45: =IF(K45="","",IFERROR(AVERAGE(N45,O45),"")) -> 0.25 | Q45: =IF(K45="","",IF(K45=0,1,0)) -> 0 | R45: =IF(OR(L45="",Baseline!$C$7=""),"",ABS(L45-Baseline!$C$7)) -> 0.16666667
A46: 5 | B46: Probe-BR|192.168.12.10 | C46: Probe-BR | D46: A | E46: Normal | F46: 2026-10-18T04:00:00Z | G46: 1 | H46: 0.5 | I46: 0.5 | J46: =IF(COUNTA(G46:I46)=0,"",3) -> 3 | K46: =IF(J46="","",COUNT(G46:I46)) -> 3 | L46: =IF(OR(K46="",K46=0),"",AVERAGE(G46:I46)) -> 0.66666667 | M46: =IF(K46="","",(J46-K46)/J46*100) -> 0 | N46: =IF(AND(ISNUMBER(G46),ISNUMBER(H46)),ABS(H46-G46),"") -> 0.5 | O46: =IF(AND(ISNUMBER(H46),ISNUMBER(I46)),ABS(I46-H46),"") -> 0 | P46: =IF(K46="","",IFERROR(AVERAGE(N46,O46),"")) -> 0.25 | Q46: =IF(K46="","",IF(K46=0,1,0)) -> 0 | R46: =IF(OR(L46="",Baseline!$C$7=""),"",ABS(L46-Baseline!$C$7)) -> 0.16666667
A47: 6 | B47: Probe-BR|192.168.12.10 | C47: Probe-BR | D47: A | E47: Normal | F47: 2026-10-18T04:01:00Z | G47: 0.5 | H47: 0.5 | I47: 0.5 | J47: =IF(COUNTA(G47:I47)=0,"",3) -> 3 | K47: =IF(J47="","",COUNT(G47:I47)) -> 3 | L47: =IF(OR(K47="",K47=0),"",AVERAGE(G47:I47)) -> 0.5 | M47: =IF(K47="","",(J47-K47)/J47*100) -> 0 | N47: =IF(AND(ISNUMBER(G47),ISNUMBER(H47)),ABS(H47-G47),"") -> 0 | O47: =IF(AND(ISNUMBER(H47),ISNUMBER(I47)),ABS(I47-H47),"") -> 0 | P47: =IF(K47="","",IFERROR(AVERAGE(N47,O47),"")) -> 0 | Q47: =IF(K47="","",IF(K47=0,1,0)) -> 0 | R47: =IF(OR(L47="",Baseline!$C$7=""),"",ABS(L47-Baseline!$C$7)) -> 0
A48: 7 | B48: Probe-BR|192.168.12.10 | C48: Probe-BR | D48: A | E48: Normal | F48: 2026-10-18T04:03:00Z | G48: 0.5 | H48: 0.5 | I48: 0.5 | J48: =IF(COUNTA(G48:I48)=0,"",3) -> 3 | K48: =IF(J48="","",COUNT(G48:I48)) -> 3 | L48: =IF(OR(K48="",K48=0),"",AVERAGE(G48:I48)) -> 0.5 | M48: =IF(K48="","",(J48-K48)/J48*100) -> 0 | N48: =IF(AND(ISNUMBER(G48),ISNUMBER(H48)),ABS(H48-G48),"") -> 0 | O48: =IF(AND(ISNUMBER(H48),ISNUMBER(I48)),ABS(I48-H48),"") -> 0 | P48: =IF(K48="","",IFERROR(AVERAGE(N48,O48),"")) -> 0 | Q48: =IF(K48="","",IF(K48=0,1,0)) -> 0 | R48: =IF(OR(L48="",Baseline!$C$7=""),"",ABS(L48-Baseline!$C$7)) -> 0
A49: 8 | B49: Probe-BR|192.168.12.10 | C49: Probe-BR | D49: A | E49: Normal | F49: 2026-10-18T04:04:00Z | G49: 0.5 | H49: 0.5 | I49: 0.5 | J49: =IF(COUNTA(G49:I49)=0,"",3) -> 3 | K49: =IF(J49="","",COUNT(G49:I49)) -> 3 | L49: =IF(OR(K49="",K49=0),"",AVERAGE(G49:I49)) -> 0.5 | M49: =IF(K49="","",(J49-K49)/J49*100) -> 0 | N49: =IF(AND(ISNUMBER(G49),ISNUMBER(H49)),ABS(H49-G49),"") -> 0 | O49: =IF(AND(ISNUMBER(H49),ISNUMBER(I49)),ABS(I49-H49),"") -> 0 | P49: =IF(K49="","",IFERROR(AVERAGE(N49,O49),"")) -> 0 | Q49: =IF(K49="","",IF(K49=0,1,0)) -> 0 | R49: =IF(OR(L49="",Baseline!$C$7=""),"",ABS(L49-Baseline!$C$7)) -> 0
A50: 9 | B50: Probe-BR|192.168.12.10 | C50: Probe-BR | D50: A | E50: Normal | F50: 2026-10-18T04:06:00Z | G50: 0.5 | H50: 0.5 | I50: 1 | J50: =IF(COUNTA(G50:I50)=0,"",3) -> 3 | K50: =IF(J50="","",COUNT(G50:I50)) -> 3 | L50: =IF(OR(K50="",K50=0),"",AVERAGE(G50:I50)) -> 0.66666667 | M50: =IF(K50="","",(J50-K50)/J50*100) -> 0 | N50: =IF(AND(ISNUMBER(G50),ISNUMBER(H50)),ABS(H50-G50),"") -> 0 | O50: =IF(AND(ISNUMBER(H50),ISNUMBER(I50)),ABS(I50-H50),"") -> 0.5 | P50: =IF(K50="","",IFERROR(AVERAGE(N50,O50),"")) -> 0.25 | Q50: =IF(K50="","",IF(K50=0,1,0)) -> 0 | R50: =IF(OR(L50="",Baseline!$C$7=""),"",ABS(L50-Baseline!$C$7)) -> 0.16666667
A51: 10 | B51: Probe-BR|192.168.12.10 | C51: Probe-BR | D51: A | E51: Normal | F51: 2026-10-18T04:07:00Z | G51: 0.5 | H51: 0.5 | I51: 0.5 | J51: =IF(COUNTA(G51:I51)=0,"",3) -> 3 | K51: =IF(J51="","",COUNT(G51:I51)) -> 3 | L51: =IF(OR(K51="",K51=0),"",AVERAGE(G51:I51)) -> 0.5 | M51: =IF(K51="","",(J51-K51)/J51*100) -> 0 | N51: =IF(AND(ISNUMBER(G51),ISNUMBER(H51)),ABS(H51-G51),"") -> 0 | O51: =IF(AND(ISNUMBER(H51),ISNUMBER(I51)),ABS(I51-H51),"") -> 0 | P51: =IF(K51="","",IFERROR(AVERAGE(N51,O51),"")) -> 0 | Q51: =IF(K51="","",IF(K51=0,1,0)) -> 0 | R51: =IF(OR(L51="",Baseline!$C$7=""),"",ABS(L51-Baseline!$C$7)) -> 0
A52: 11 | B52: Probe-BR|192.168.12.10 | C52: Probe-BR | D52: A | E52: Normal | F52: 2026-10-18T04:09:00Z | G52: 1 | H52: 0.5 | I52: 0.5 | J52: =IF(COUNTA(G52:I52)=0,"",3) -> 3 | K52: =IF(J52="","",COUNT(G52:I52)) -> 3 | L52: =IF(OR(K52="",K52=0),"",AVERAGE(G52:I52)) -> 0.66666667 | M52: =IF(K52="","",(J52-K52)/J52*100) -> 0 | N52: =IF(AND(ISNUMBER(G52),ISNUMBER(H52)),ABS(H52-G52),"") -> 0.5 | O52: =IF(AND(ISNUMBER(H52),ISNUMBER(I52)),ABS(I52-H52),"") -> 0 | P52: =IF(K52="","",IFERROR(AVERAGE(N52,O52),"")) -> 0.25 | Q52: =IF(K52="","",IF(K52=0,1,0)) -> 0 | R52: =IF(OR(L52="",Baseline!$C$7=""),"",ABS(L52-Baseline!$C$7)) -> 0.16666667
A53: 12 | B53: Probe-BR|192.168.12.10 | C53: Probe-BR | D53: A | E53: Normal | F53: 2026-10-18T04:11:00Z | G53: 0.5 | H53: 0.5 | I53: 0.5 | J53: =IF(COUNTA(G53:I53)=0,"",3) -> 3 | K53: =IF(J53="","",COUNT(G53:I53)) -> 3 | L53: =IF(OR(K53="",K53=0),"",AVERAGE(G53:I53)) -> 0.5 | M53: =IF(K53="","",(J53-K53)/J53*100) -> 0 | N53: =IF(AND(ISNUMBER(G53),ISNUMBER(H53)),ABS(H53-G53),"") -> 0 | O53: =IF(AND(ISNUMBER(H53),ISNUMBER(I53)),ABS(I53-H53),"") -> 0 | P53: =IF(K53="","",IFERROR(AVERAGE(N53,O53),"")) -> 0 | Q53: =IF(K53="","",IF(K53=0,1,0)) -> 0 | R53: =IF(OR(L53="",Baseline!$C$7=""),"",ABS(L53-Baseline!$C$7)) -> 0
...

Sheet Baseline
A1: Ficha de baseline por fluxo (Período A)
A2: Calculada por fórmula a partir da aba Coleta. Latências em ms.
A4: fluxo_id | B4: rota | C4: mediana_ms | D4: MAD_ms | E4: IQR_ms | F4: jitter típico (ms) | G4: perda típica (%) | H4: taxa de resposta | I4: rajadas coletadas | J4: status
A5: Probe-BR|192.168.10.10 | B5: BR → BR | C5: =IFERROR(MEDIAN(Coleta!L2:L21),"") -> 0.5 | D5: =IFERROR(MEDIAN(Coleta!R2:R21),"") -> 0 | E5: =IFERROR(QUARTILE(Coleta!L2:L21,3)-QUARTILE(Coleta!L2:L21,1),"") -> 0.16666667 | F5: =IFERROR(MEDIAN(Coleta!P2:P21),"") -> 0 | G5: =IFERROR(AVERAGE(Coleta!M2:M21),"") -> 0 | H5: =IFERROR(SUM(Coleta!K2:K21)/SUM(Coleta!J2:J21),"") -> 1 | I5: =COUNT(Coleta!J2:J21) -> 20 | J5: =IF(I5>=20,"Completo",I5&"/20") -> Completo
A6: Probe-BR|192.168.11.10 | B6: BR → UY | C6: =IFERROR(MEDIAN(Coleta!L22:L41),"") -> 0.5 | D6: =IFERROR(MEDIAN(Coleta!R22:R41),"") -> 0 | E6: =IFERROR(QUARTILE(Coleta!L22:L41,3)-QUARTILE(Coleta!L22:L41,1),"") -> 1.8333333 | F6: =IFERROR(MEDIAN(Coleta!P22:P41),"") -> 0 | G6: =IFERROR(AVERAGE(Coleta!M22:M41),"") -> 1.6666667 | H6: =IFERROR(SUM(Coleta!K22:K41)/SUM(Coleta!J22:J41),"") -> 0.98333333 | I6: =COUNT(Coleta!J22:J41) -> 20 | J6: =IF(I6>=20,"Completo",I6&"/20") -> Completo
A7: Probe-BR|192.168.12.10 | B7: BR → BO | C7: =IFERROR(MEDIAN(Coleta!L42:L61),"") -> 0.5 | D7: =IFERROR(MEDIAN(Coleta!R42:R61),"") -> 0 | E7: =IFERROR(QUARTILE(Coleta!L42:L61,3)-QUARTILE(Coleta!L42:L61,1),"") -> 0.16666667 | F7: =IFERROR(MEDIAN(Coleta!P42:P61),"") -> 0 | G7: =IFERROR(AVERAGE(Coleta!M42:M61),"") -> 1.6666667 | H7: =IFERROR(SUM(Coleta!K42:K61)/SUM(Coleta!J42:J61),"") -> 0.98333333 | I7: =COUNT(Coleta!J42:J61) -> 20 | J7: =IF(I7>=20,"Completo",I7&"/20") -> Completo
A8: Probe-BR|192.168.42.10 | B8: BR → JP | C8: =IFERROR(MEDIAN(Coleta!L62:L81),"") -> 8.6666667 | D8: =IFERROR(MEDIAN(Coleta!R62:R81),"") -> 3.25 | E8: =IFERROR(QUARTILE(Coleta!L62:L81,3)-QUARTILE(Coleta!L62:L81,1),"") -> 7.0833333 | F8: =IFERROR(MEDIAN(Coleta!P62:P81),"") -> 7.5 | G8: =IFERROR(AVERAGE(Coleta!M62:M81),"") -> 1.6666667 | H8: =IFERROR(SUM(Coleta!K62:K81)/SUM(Coleta!J62:J81),"") -> 0.98333333 | I8: =COUNT(Coleta!J62:J81) -> 20 | J8: =IF(I8>=20,"Completo",I8&"/20") -> Completo
A9: Probe-BR|192.168.40.10 | B9: BR → IN | C9: =IFERROR(MEDIAN(Coleta!L82:L101),"") -> 7.5 | D9: =IFERROR(MEDIAN(Coleta!R82:R101),"") -> 4.3333333 | E9: =IFERROR(QUARTILE(Coleta!L82:L101,3)-QUARTILE(Coleta!L82:L101,1),"") -> 8.4166667 | F9: =IFERROR(MEDIAN(Coleta!P82:P101),"") -> 9 | G9: =IFERROR(AVERAGE(Coleta!M82:M101),"") -> 1.6666667 | H9: =IFERROR(SUM(Coleta!K82:K101)/SUM(Coleta!J82:J101),"") -> 0.98333333 | I9: =COUNT(Coleta!J82:J101) -> 20 | J9: =IF(I9>=20,"Completo",I9&"/20") -> Completo
A10: Probe-BR|192.168.30.10 | B10: BR → ZA | C10: =IFERROR(MEDIAN(Coleta!L102:L121),"") -> 8.3333333 | D10: =IFERROR(MEDIAN(Coleta!R102:R121),"") -> 2.25 | E10: =IFERROR(QUARTILE(Coleta!L102:L121,3)-QUARTILE(Coleta!L102:L121,1),"") -> 4.125 | F10: =IFERROR(MEDIAN(Coleta!P102:P121),"") -> 9.75 | G10: =IFERROR(AVERAGE(Coleta!M102:M121),"") -> 1.6666667 | H10: =IFERROR(SUM(Coleta!K102:K121)/SUM(Coleta!J102:J121),"") -> 0.98333333 | I10: =COUNT(Coleta!J102:J121) -> 20 | J10: =IF(I10>=20,"Completo",I10&"/20") -> Completo
A11: Probe-DE|192.168.20.10 | B11: DE → DE | C11: =IFERROR(MEDIAN(Coleta!L122:L141),"") -> 0.5 | D11: =IFERROR(MEDIAN(Coleta!R122:R141),"") -> 0 | E11: =IFERROR(QUARTILE(Coleta!L122:L141,3)-QUARTILE(Coleta!L122:L141,1),"") -> 0.16666667 | F11: =IFERROR(MEDIAN(Coleta!P122:P141),"") -> 0 | G11: =IFERROR(AVERAGE(Coleta!M122:M141),"") -> 0 | H11: =IFERROR(SUM(Coleta!K122:K141)/SUM(Coleta!J122:J141),"") -> 1 | I11: =COUNT(Coleta!J122:J141) -> 20 | J11: =IF(I11>=20,"Completo",I11&"/20") -> Completo
A12: Probe-DE|192.168.21.10 | B12: DE → PT | C12: =IFERROR(MEDIAN(Coleta!L142:L161),"") -> 0.5 | D12: =IFERROR(MEDIAN(Coleta!R142:R161),"") -> 0 | E12: =IFERROR(QUARTILE(Coleta!L142:L161,3)-QUARTILE(Coleta!L142:L161,1),"") -> 0.16666667 | F12: =IFERROR(MEDIAN(Coleta!P142:P161),"") -> 0 | G12: =IFERROR(AVERAGE(Coleta!M142:M161),"") -> 1.6666667 | H12: =IFERROR(SUM(Coleta!K142:K161)/SUM(Coleta!J142:J161),"") -> 0.98333333 | I12: =COUNT(Coleta!J142:J161) -> 20 | J12: =IF(I12>=20,"Completo",I12&"/20") -> Completo
A13: Probe-AR|192.168.13.10 | B13: AR → AR | C13: =IFERROR(MEDIAN(Coleta!L162:L181),"") -> 0.5 | D13: =IFERROR(MEDIAN(Coleta!R162:R181),"") -> 0 | E13: =IFERROR(QUARTILE(Coleta!L162:L181,3)-QUARTILE(Coleta!L162:L181,1),"") -> 0 | F13: =IFERROR(MEDIAN(Coleta!P162:P181),"") -> 0 | G13: =IFERROR(AVERAGE(Coleta!M162:M181),"") -> 0 | H13: =IFERROR(SUM(Coleta!K162:K181)/SUM(Coleta!J162:J181),"") -> 1 | I13: =COUNT(Coleta!J162:J181) -> 20 | J13: =IF(I13>=20,"Completo",I13&"/20") -> Completo
A14: Probe-ES|192.168.23.10 | B14: ES → PL | C14: =IFERROR(MEDIAN(Coleta!L182:L201),"") -> 0.5 | D14: =IFERROR(MEDIAN(Coleta!R182:R201),"") -> 0 | E14: =IFERROR(QUARTILE(Coleta!L182:L201,3)-QUARTILE(Coleta!L182:L201,1),"") -> 0.16666667 | F14: =IFERROR(MEDIAN(Coleta!P182:P201),"") -> 0 | G14: =IFERROR(AVERAGE(Coleta!M182:M201),"") -> 0 | H14: =IFERROR(SUM(Coleta!K182:K201)/SUM(Coleta!J182:J201),"") -> 1 | I14: =COUNT(Coleta!J182:J201) -> 20 | J14: =IF(I14>=20,"Completo",I14&"/20") -> Completo
A15: Probe-ZA|192.168.31.10 | B15: ZA → KE | C15: =IFERROR(MEDIAN(Coleta!L202:L221),"") -> 0.5 | D15: =IFERROR(MEDIAN(Coleta!R202:R221),"") -> 0 | E15: =IFERROR(QUARTILE(Coleta!L202:L221,3)-QUARTILE(Coleta!L202:L221,1),"") -> 0.16666667 | F15: =IFERROR(MEDIAN(Coleta!P202:P221),"") -> 0 | G15: =IFERROR(AVERAGE(Coleta!M202:M221),"") -> 1.6666667 | H15: =IFERROR(SUM(Coleta!K202:K221)/SUM(Coleta!J202:J221),"") -> 0.98333333 | I15: =COUNT(Coleta!J202:J221) -> 20 | J15: =IF(I15>=20,"Completo",I15&"/20") -> Completo
A16: Probe-IN|192.168.41.10 | B16: IN → SG | C16: =IFERROR(MEDIAN(Coleta!L222:L241),"") -> 0.5 | D16: =IFERROR(MEDIAN(Coleta!R222:R241),"") -> 0 | E16: =IFERROR(QUARTILE(Coleta!L222:L241,3)-QUARTILE(Coleta!L222:L241,1),"") -> 0.041666667 | F16: =IFERROR(MEDIAN(Coleta!P222:P241),"") -> 0 | G16: =IFERROR(AVERAGE(Coleta!M222:M241),"") -> 1.6666667 | H16: =IFERROR(SUM(Coleta!K222:K241)/SUM(Coleta!J222:J241),"") -> 0.98333333 | I16: =COUNT(Coleta!J222:J241) -> 20 | J16: =IF(I16>=20,"Completo",I16&"/20") -> Completo
A18: Nota: 20 rajadas por fluxo (60 RTT) é a versão reduzida da ATA; abaixo do piso de 1.500 RTT do repositório (baseline_insuficiente).

Sheet medicoes_pt.csv.
A1: timestamp | B1: fluxo_id | C1: periodo | D1: cenario | E1: sent | F1: rcvd | G1: latencia_ms | H1: perda_pct | I1: jitter_ms | J1: timeout_atual | K1: probe_id
A2: =IF(Coleta!$J2="","",Coleta!F2) -> 2026-10-18T01:50:00Z | B2: =IF(Coleta!$J2="","",Coleta!B2) -> Probe-BR|192.168.10.10 | C2: =IF(Coleta!$J2="","",Coleta!D2) -> A | D2: =IF(Coleta!$J2="","",Coleta!E2) -> Normal | E2: =IF(Coleta!$J2="","",Coleta!J2) -> 3 | F2: =IF(Coleta!$J2="","",Coleta!K2) -> 3 | G2: =IF(Coleta!$J2="","",Coleta!L2) -> 0.5 | H2: =IF(Coleta!$J2="","",Coleta!M2) -> 0 | I2: =IF(Coleta!$J2="","",Coleta!P2) -> 0 | J2: =IF(Coleta!$J2="","",Coleta!Q2) -> 0 | K2: =IF(Coleta!$J2="","",Coleta!C2) -> Probe-BR
A3: =IF(Coleta!$J3="","",Coleta!F3) -> 2026-10-18T02:08:00Z | B3: =IF(Coleta!$J3="","",Coleta!B3) -> Probe-BR|192.168.10.10 | C3: =IF(Coleta!$J3="","",Coleta!D3) -> A | D3: =IF(Coleta!$J3="","",Coleta!E3) -> Normal | E3: =IF(Coleta!$J3="","",Coleta!J3) -> 3 | F3: =IF(Coleta!$J3="","",Coleta!K3) -> 3 | G3: =IF(Coleta!$J3="","",Coleta!L3) -> 0.5 | H3: =IF(Coleta!$J3="","",Coleta!M3) -> 0 | I3: =IF(Coleta!$J3="","",Coleta!P3) -> 0 | J3: =IF(Coleta!$J3="","",Coleta!Q3) -> 0 | K3: =IF(Coleta!$J3="","",Coleta!C3) -> Probe-BR
A4: =IF(Coleta!$J4="","",Coleta!F4) -> 2026-10-18T02:15:00Z | B4: =IF(Coleta!$J4="","",Coleta!B4) -> Probe-BR|192.168.10.10 | C4: =IF(Coleta!$J4="","",Coleta!D4) -> A | D4: =IF(Coleta!$J4="","",Coleta!E4) -> Normal | E4: =IF(Coleta!$J4="","",Coleta!J4) -> 3 | F4: =IF(Coleta!$J4="","",Coleta!K4) -> 3 | G4: =IF(Coleta!$J4="","",Coleta!L4) -> 0.5 | H4: =IF(Coleta!$J4="","",Coleta!M4) -> 0 | I4: =IF(Coleta!$J4="","",Coleta!P4) -> 0 | J4: =IF(Coleta!$J4="","",Coleta!Q4) -> 0 | K4: =IF(Coleta!$J4="","",Coleta!C4) -> Probe-BR
A5: =IF(Coleta!$J5="","",Coleta!F5) -> 2026-10-18T02:20:00Z | B5: =IF(Coleta!$J5="","",Coleta!B5) -> Probe-BR|192.168.10.10 | C5: =IF(Coleta!$J5="","",Coleta!D5) -> A | D5: =IF(Coleta!$J5="","",Coleta!E5) -> Normal | E5: =IF(Coleta!$J5="","",Coleta!J5) -> 3 | F5: =IF(Coleta!$J5="","",Coleta!K5) -> 3 | G5: =IF(Coleta!$J5="","",Coleta!L5) -> 5 | H5: =IF(Coleta!$J5="","",Coleta!M5) -> 0 | I5: =IF(Coleta!$J5="","",Coleta!P5) -> 6.75 | J5: =IF(Coleta!$J5="","",Coleta!Q5) -> 0 | K5: =IF(Coleta!$J5="","",Coleta!C5) -> Probe-BR
A6: =IF(Coleta!$J6="","",Coleta!F6) -> 2026-10-18T02:36:00Z | B6: =IF(Coleta!$J6="","",Coleta!B6) -> Probe-BR|192.168.10.10 | C6: =IF(Coleta!$J6="","",Coleta!D6) -> A | D6: =IF(Coleta!$J6="","",Coleta!E6) -> Normal | E6: =IF(Coleta!$J6="","",Coleta!J6) -> 3 | F6: =IF(Coleta!$J6="","",Coleta!K6) -> 3 | G6: =IF(Coleta!$J6="","",Coleta!L6) -> 0.66666667 | H6: =IF(Coleta!$J6="","",Coleta!M6) -> 0 | I6: =IF(Coleta!$J6="","",Coleta!P6) -> 0.5 | J6: =IF(Coleta!$J6="","",Coleta!Q6) -> 0 | K6: =IF(Coleta!$J6="","",Coleta!C6) -> Probe-BR
A7: =IF(Coleta!$J7="","",Coleta!F7) -> 2026-10-18T02:39:00Z | B7: =IF(Coleta!$J7="","",Coleta!B7) -> Probe-BR|192.168.10.10 | C7: =IF(Coleta!$J7="","",Coleta!D7) -> A | D7: =IF(Coleta!$J7="","",Coleta!E7) -> Normal | E7: =IF(Coleta!$J7="","",Coleta!J7) -> 3 | F7: =IF(Coleta!$J7="","",Coleta!K7) -> 3 | G7: =IF(Coleta!$J7="","",Coleta!L7) -> 0.66666667 | H7: =IF(Coleta!$J7="","",Coleta!M7) -> 0 | I7: =IF(Coleta!$J7="","",Coleta!P7) -> 0.5 | J7: =IF(Coleta!$J7="","",Coleta!Q7) -> 0 | K7: =IF(Coleta!$J7="","",Coleta!C7) -> Probe-BR
A8: =IF(Coleta!$J8="","",Coleta!F8) -> 2026-10-18T02:40:00Z | B8: =IF(Coleta!$J8="","",Coleta!B8) -> Probe-BR|192.168.10.10 | C8: =IF(Coleta!$J8="","",Coleta!D8) -> A | D8: =IF(Coleta!$J8="","",Coleta!E8) -> Normal | E8: =IF(Coleta!$J8="","",Coleta!J8) -> 3 | F8: =IF(Coleta!$J8="","",Coleta!K8) -> 3 | G8: =IF(Coleta!$J8="","",Coleta!L8) -> 0.5 | H8: =IF(Coleta!$J8="","",Coleta!M8) -> 0 | I8: =IF(Coleta!$J8="","",Coleta!P8) -> 0 | J8: =IF(Coleta!$J8="","",Coleta!Q8) -> 0 | K8: =IF(Coleta!$J8="","",Coleta!C8) -> Probe-BR
A9: =IF(Coleta!$J9="","",Coleta!F9) -> 2026-10-18T02:43:00Z | B9: =IF(Coleta!$J9="","",Coleta!B9) -> Probe-BR|192.168.10.10 | C9: =IF(Coleta!$J9="","",Coleta!D9) -> A | D9: =IF(Coleta!$J9="","",Coleta!E9) -> Normal | E9: =IF(Coleta!$J9="","",Coleta!J9) -> 3 | F9: =IF(Coleta!$J9="","",Coleta!K9) -> 3 | G9: =IF(Coleta!$J9="","",Coleta!L9) -> 0.66666667 | H9: =IF(Coleta!$J9="","",Coleta!M9) -> 0 | I9: =IF(Coleta!$J9="","",Coleta!P9) -> 0.5 | J9: =IF(Coleta!$J9="","",Coleta!Q9) -> 0 | K9: =IF(Coleta!$J9="","",Coleta!C9) -> Probe-BR
A10: =IF(Coleta!$J10="","",Coleta!F10) -> 2026-10-18T02:46:00Z | B10: =IF(Coleta!$J10="","",Coleta!B10) -> Probe-BR|192.168.10.10 | C10: =IF(Coleta!$J10="","",Coleta!D10) -> A | D10: =IF(Coleta!$J10="","",Coleta!E10) -> Normal | E10: =IF(Coleta!$J10="","",Coleta!J10) -> 3 | F10: =IF(Coleta!$J10="","",Coleta!K10) -> 3 | G10: =IF(Coleta!$J10="","",Coleta!L10) -> 0.5 | H10: =IF(Coleta!$J10="","",Coleta!M10) -> 0 | I10: =IF(Coleta!$J10="","",Coleta!P10) -> 0 | J10: =IF(Coleta!$J10="","",Coleta!Q10) -> 0 | K10: =IF(Coleta!$J10="","",Coleta!C10) -> Probe-BR
A11: =IF(Coleta!$J11="","",Coleta!F11) -> 2026-10-18T02:49:00Z | B11: =IF(Coleta!$J11="","",Coleta!B11) -> Probe-BR|192.168.10.10 | C11: =IF(Coleta!$J11="","",Coleta!D11) -> A | D11: =IF(Coleta!$J11="","",Coleta!E11) -> Normal | E11: =IF(Coleta!$J11="","",Coleta!J11) -> 3 | F11: =IF(Coleta!$J11="","",Coleta!K11) -> 3 | G11: =IF(Coleta!$J11="","",Coleta!L11) -> 0.5 | H11: =IF(Coleta!$J11="","",Coleta!M11) -> 0 | I11: =IF(Coleta!$J11="","",Coleta!P11) -> 0 | J11: =IF(Coleta!$J11="","",Coleta!Q11) -> 0 | K11: =IF(Coleta!$J11="","",Coleta!C11) -> Probe-BR
A12: =IF(Coleta!$J12="","",Coleta!F12) -> 2026-10-18T02:51:00Z | B12: =IF(Coleta!$J12="","",Coleta!B12) -> Probe-BR|192.168.10.10 | C12: =IF(Coleta!$J12="","",Coleta!D12) -> A | D12: =IF(Coleta!$J12="","",Coleta!E12) -> Normal | E12: =IF(Coleta!$J12="","",Coleta!J12) -> 3 | F12: =IF(Coleta!$J12="","",Coleta!K12) -> 3 | G12: =IF(Coleta!$J12="","",Coleta!L12) -> 0.5 | H12: =IF(Coleta!$J12="","",Coleta!M12) -> 0 | I12: =IF(Coleta!$J12="","",Coleta!P12) -> 0 | J12: =IF(Coleta!$J12="","",Coleta!Q12) -> 0 | K12: =IF(Coleta!$J12="","",Coleta!C12) -> Probe-BR
A13: =IF(Coleta!$J13="","",Coleta!F13) -> 2026-10-18T02:53:00Z | B13: =IF(Coleta!$J13="","",Coleta!B13) -> Probe-BR|192.168.10.10 | C13: =IF(Coleta!$J13="","",Coleta!D13) -> A | D13: =IF(Coleta!$J13="","",Coleta!E13) -> Normal | E13: =IF(Coleta!$J13="","",Coleta!J13) -> 3 | F13: =IF(Coleta!$J13="","",Coleta!K13) -> 3 | G13: =IF(Coleta!$J13="","",Coleta!L13) -> 7.6666667 | H13: =IF(Coleta!$J13="","",Coleta!M13) -> 0 | I13: =IF(Coleta!$J13="","",Coleta!P13) -> 10.75 | J13: =IF(Coleta!$J13="","",Coleta!Q13) -> 0 | K13: =IF(Coleta!$J13="","",Coleta!C13) -> Probe-BR
... A241: =IF(Coleta!$J241="","",Coleta!F241) -> 2026-10-18T18:44:00Z | B241: =IF(Coleta!$J241="","",Coleta!B241) -> Probe-IN|192.168.41.10 | C241: =IF(Coleta!$J241="","",Coleta!D241) -> A | D241: =IF(Coleta!$J241="","",Coleta!E241) -> Normal | E241: =IF(Coleta!$J241="","",Coleta!J241) -> 3 | F241: =IF(Coleta!$J241="","",Coleta!K241) -> 3 | G241: =IF(Coleta!$J241="","",Coleta!L241) -> 0.5 | H241: =IF(Coleta!$J241="","",Coleta!M241) -> 0 | I241: =IF(Coleta!$J241="","",Coleta!P241) -> 0 | J241: =IF(Coleta!$J241="","",Coleta!Q241) -> 0 | K241: =IF(Coleta!$J241="","",Coleta!C241) -> Probe-IN
A242: 2026-10-18T20:20:00Z | B242: Probe-BR|192.168.42.10 | C242: B | D242: Normal | E242: 3 | F242: 3 | G242: 14.666667 | H242: 0 | I242: 11 | J242: 0 | K242: Probe-BR
A243: 2026-10-18T20:43:00Z | B243: Probe-BR|192.168.42.10 | C243: B | D243: Normal | E243: 3 | F243: 3 | G243: 1.6666667 | H243: 0 | I243: 1 | J243: 0 | K243: Probe-BR
A244: 2026-10-18T20:44:00Z | B244: Probe-BR|192.168.42.10 | C244: B | D244: Normal | E244: 3 | F244: 3 | G244: 1.3333333 | H244: 0 | I244: 1 | J244: 0 | K244: Probe-BR
A245: 2026-10-18T20:47:00Z | B245: Probe-BR|192.168.42.10 | C245: B | D245: Normal | E245: 3 | F245: 3 | G245: 4 | H245: 0 | I245: 4.5 | J245: 0 | K245: Probe-BR
A246: 2026-10-18T20:48:00Z | B246: Probe-BR|192.168.42.10 | C246: B | D246: Normal | E246: 3 | F246: 3 | G246: 10 | H246: 0 | I246: 9.5 | J246: 0 | K246: Probe-BR
A247: 2026-10-18T20:49:00Z | B247: Probe-BR|192.168.42.10 | C247: B | D247: Normal | E247: 3 | F247: 3 | G247: 8 | H247: 0 | I247: 7.5 | J247: 0 | K247: Probe-BR
A248: 2026-10-18T20:50:00Z | B248: Probe-BR|192.168.42.10 | C248: B | D248: Normal | E248: 3 | F248: 3 | G248: 1 | H248: 0 | I248: 0 | J248: 0 | K248: Probe-BR
A249: 2026-10-18T20:52:00Z | B249: Probe-BR|192.168.42.10 | C249: B | D249: Normal | E249: 3 | F249: 3 | G249: 11.666667 | H249: 0 | I249: 9.5 | J249: 0 | K249: Probe-BR
A250: 2026-10-18T20:53:00Z | B250: Probe-BR|192.168.42.10 | C250: B | D250: Normal | E250: 3 | F250: 3 | G250: 16.333333 | H250: 0 | I250: 14.5 | J250: 0 | K250: Probe-BR
A251: 2026-10-18T20:53:00Z | B251: Probe-BR|192.168.42.10 | C251: B | D251: Normal | E251: 3 | F251: 3 | G251: 11.333333 | H251: 0 | I251: 10 | J251: 0 | K251: Probe-BR
A252: 2026-10-18T20:54:00Z | B252: Probe-BR|192.168.42.10 | C252: B | D252: Normal | E252: 3 | F252: 3 | G252: 1.6666667 | H252: 0 | I252: 1 | J252: 0 | K252: Probe-BR
A253: 2026-10-18T20:55:00Z | B253: Probe-BR|192.168.42.10 | C253: B | D253: Normal | E253: 3 | F253: 3 | G253: 2.3333333 | H253: 0 | I253: 0.5 | J253: 0 | K253: Probe-BR
... A321: 2026-10-18T23:05:03Z | B321: Probe-BR|192.168.42.10 | C321: B | D321: Queda de enlace | E321: 3 | F321: 0 | G321: 0 | H321: 100 | I321: 0 | J321: 1 | K321: Probe-BR
